Workbook

Sheet 1°K
F1: Centro de Investigación Educativa Colegio San Diego | S1: ACEPTADOS POR CORPORATIVO
F2: Punta el Campanario #183 Col. Bahia de San Martín CP 96536 | S2: PAGOS DE HIJOS DE MAESTROS
F3: PREESCOLAR 30PJN1037Z PRIMARIA 30PPR3773B SECUNDARIA 30PES0033G | S3: MES PAGADO
D4: FACTURA | F4: CICLO ESCOLAR 2024-2025 | S4: ALUMNO DADO DE BAJA
S5: IRRIGULARIDADES
B7: N° | C7: MATRICULA | D7: NOMBRE DEL ALUMNO | E7: PROMOCION | F7: INSCRIPCION | G7: FOLIO | H7: FECHA | I7: MATERIAL | J7: FECHA | K7: FOLIO | L7: ARANCEL | M7: FECHA | N7: FOLIO | O7: LIBROS | P7: FECHA | Q7: FOLIO | R7: UNIFORMES | S7: FECHA | T7: FOLIO | U7: PLAN PAGO | V7: BECA | W7: COLEG | X7: 10 meses
A8: 921 173 2609 | B8: FALTA DE FIRMAR | C8: NUEVO INGRESO | D8: ADRIAN GABRIEL CASTELLANOS VARGAS | E8: ENERO-FEBRERO | F8: GRATIS | G8: GRATIS | H8: 45728 | I8: 2990 | J8: 45728 | K8: 30065 | L8: 2390 | M8: 45728 | N8: 030065 | O8: 3900 | P8: 45798 | Q8: 023933 | U8: 10 MESES | V8: 0.3 | W8: 2394
A9: 921 291 0428 | B9: FIRMO DOCUMENTOS | C9: NUEVO INGRESO | D9: ELIAS DANIEL CRUZ LOPEZ | E9: MARZO-JUNIO | F9: GRATIS | G9: GRATIS | H9: 45825 | I9: 2093 | J9: 45825 | K9: 63415250 | L9: 1673 | M9: 45825 | N9: 63415250 | O9: 1980 | P9: 45903 | Q9: 3012346
A10: 921 280 1194 | C10: NUEVO INGRESO | D10: HELENA POBLETE PEÑA | E10: MARZO-JUNIO | F10: GRATIS | G10: GRATIS | H10: 45895 | I10: 1195 | J10: 45895 | K10: 692208 | L10: 1245 | M10: 45895 | N10: 692208 | U10: 12 MESES | V10: 0.3 | W10: 1852
Z13: 7213
B19: COLEGIATURA
B20: N° | C20: MATRICULA | D20: NOMBRE DEL ALUMNO | E20: AGOSTO | H20: SEPTIEMBRE | K20: OCTUBRE | N20: NOVIEMBRE | Q20: DICIEMBRE | T20: ENERO | W20: JULIO | Z20: FEBRERO | AC20: MARZO | AF20: ABRIL | AI20: MAYO | AL20: JUNIO
E21: MONTO | F21: FECHA | G21: FOLIO | H21: MONTO | I21: FECHA | J21: FOLIO | K21: MONTO | L21: FECHA | M21: FOLIO | N21: MONTO | O21: FECHA | P21: FOLIO | Q21: MONTO | R21: FECHA | S21: FOLIO | T21: MONTO | U21: FECHA | V21: FOLIO | W21: MONTO | X21: FECHA | Y21: FOLIO | Z21: MONTO | AA21: FECHA | AB21: FOLIO | AC21: MONTO | AD21: FECHA | AE21: FOLIO | AF21: MONTO | AG21: FECHA | AH21: FOLIO | AI21: MONTO | AJ21: FECHA | AK21: FOLIO | AL21: MONTO | AM21: FECHA | AN21: FOLIO
D22: =D8 -> ADRIAN GABRIEL CASTELLANOS VARGAS | H22: 2394 | I22: 45903 | J22: 662152 | K22: 2394 | L22: 45933 | M22: 351478 | N22: 2394 | O22: 45965 | P22: 680625 | Q22: 2394 | R22: 45995 | S22: 587592 | T22: 2394 | U22: 46027 | V22: SF | Z22: 2394 | AA22: 46057 | AB22: 829169 | AC22: 2394 | AD22: 46086 | AE22: SF | AF22: 2394 | AG22: 46117 | AH22: 54896123 | AI22: 2394 | AJ22: 46140 | AK22: 427092 TD | AL22: 2394 | AM22: 46174 | AN22: 82731 TD | AO22: fac ok
D23: =D9 -> ELIAS DANIEL CRUZ LOPEZ | H23: 2394 | I23: 45901 | J23: 3900479 | K23: 2394 | L23: 45935 | M23: 3900458 | N23: 2394 | O23: 45966 | P23: 68654212 | Q23: 2394 | R23: 45996 | S23: 91731157 | T23: 2394 | U23: 46387 | V23: 74572516 | Z23: 2394 | AA23: 46056 | AB23: 43068784 | AC23: 2394 | AD23: 46084 | AE23: 23256555 | AF23: 2394 | AG23: 46116 | AH23: 22936963 | AI23: 2394 | AJ23: 46146 | AK23: 40105282 | AL23: 2394 | AM23: 46179 | AN23: 20930613 | AO23: fac ok
D24: =D10 -> HELENA POBLETE PEÑA | H24: 1995 | I24: 45895 | J24: 692208 | K24: 1852 | L24: 45698 | M24: 89983 | N24: 1852 | O24: 45966 | P24: 552233 | Q24: 1852 | R24: 45996 | S24: 24151418 | T24: 1852 | U24: 46027 | V24: SF | Z24: 1852 | AA24: 46058 | AB24: 953212 | AC24: 1852 | AD24: 46086 | AE24: SF | AF24: 1852 | AG24: 46118 | AH24: 28873685 | AI24: 1852 | AJ24: 46148 | AK24: 289 (tarjeta cred) | AL24: 1852 | AM24: 46178 | AN24: 158878 TC | AO24: fac ok

Sheet 2°K
F1: Centro de Investigación Educativa Colegio San Diego | S1: ACEPTADOS POR CORPORATIVO
F2: Punta el Campanario #183 Col. Bahia de San Martín CP 96536 | S2: PAGOS DE HIJOS DE MAESTROS
F3: PREESCOLAR 30PJN1037Z PRIMARIA 30PPR3773B SECUNDARIA 30PES0033G | S3: MES PAGADO
D4: FACTURA | F4: CICLO ESCOLAR 2024-2025 | S4: ALUMNO DADO DE BAJA
S5: IRRIGULARIDADES
B7: N° | C7: MATRICULA | D7: NOMBRE DEL ALUMNO | E7: PROMOCION | F7: INSCRIPCION | G7: FOLIO | H7: FECHA | I7: MATERIAL | J7: FECHA | K7: FOLIO | L7: ARANCEL | M7: FECHA | N7: FOLIO | O7: LIBROS | P7: FECHA | Q7: FOLIO | R7: UNIFORMES | S7: FECHA | T7: FOLIO | U7: PLAN PAGO | V7: BECA | W7: COLEG | X7: 10 meses | Z7: 2700 | AA7: 0.3 | AB7: =Z7*AA7 -> 810 | AC7: =Z7-AB7 -> 1890
A8: 921 266 6224 | C8: NUEVO INGRESO | D8: DANAE GARCÍA JIMÉNEZ | E8: NOVIEMBRE-DICIEMBRE | F8: 1450 | G8: 85906482800336200´ | H8: 45653 | I8: 2990 | J8: 45653 | K8: 85906482800336200´ | L8: 2390 | M8: 45653 | N8: 85906482800336200´ | O8: 3900 | P8: 45803 | Q8: 8.5902325e+16 | R8: 3085 | S8: 45887 | T8: 784769 | U8: 12 meses | V8: 0.25 | W8: 1995 | Z8: 3108.8 | AA8: 0.3 | AB8: =Z8*AA8 -> 932.64 | AC8: =Z8-AB8 -> 2176.16
A9: 556 932 1515 | C9: NUEVO INGRESO | D9: SARA ANALI CRUZ PORTILLA | E9: MARZO-JUNIO | F9: 1450 | G9: 5020242 | H9: 45853 | I9: 2990 | J9: 45853 | K9: 5020242 | L9: 2390 | M9: 45853 | N9: 5020242 | O9: 4400 | U9: 12 meses | V9: 0.25 | W9: 1995
A10: 922 220 8188 | C10: NUEVO INGRESO | D10: JOHANA CRUZ MURGIA | E10: MARZO-JUNIO | F10: 1450 | G10: 102LL1 | H10: 45847 | I10: 2990 | J10: 45847 | K10: 102LL1 | L10: 2390 | M10: 45847 | N10: 102LL1 | O10: 4400 | P10: 45847 | Q10: 102LL1 | R10: 3085 | S10: 45847 | T10: 102LL1 | U10: 10 meses | V10: 0.35 | W10: 2223
A11: 923 108 1626 | C11: NUEVO INGRESO | D11: GAEL SANDOVAL GARCIA | E11: MARZO-JUNIO
A12: 229 465 3459 | C12: NUEVO INGRESO | D12: AITANA REBECA FERNÁNDEZ CRUZ | E12: MARZO-JUNIO | F12: GRATIS | G12: GRATIS | H12: 45897 | I12: 500 | J12: 45897 | K12: 2808250 | L12: GRATIS | M12: 45897 | N12: GRATIS | O12: 2200 | P12: 45905 | Q12: 1375802219 | U12: 12 meses | V12: 0.3 | W12: 1995
B19: COLEGIATURA
B20: N° | C20: MATRICULA | D20: NOMBRE DEL ALUMNO | E20: AGOSTO | H20: SEPTIEMBRE | K20: OCTUBRE | N20: NOVIEMBRE | Q20: DICIEMBRE | T20: ENERO | W20: JULIO | Z20: FEBRERO | AC20: MARZO | AF20: ABRIL | AI20: MAYO | AL20: JUNIO
E21: MONTO | F21: FECHA | G21: FOLIO | H21: MONTO | I21: FECHA | J21: FOLIO | K21: MONTO | L21: FECHA | M21: FOLIO | N21: MONTO | O21: FECHA | P21: FOLIO | Q21: MONTO | R21: FECHA | S21: FOLIO | T21: MONTO | U21: FECHA | V21: FOLIO | W21: MONTO | X21: FECHA | Y21: FOLIO | Z21: MONTO | AA21: FECHA | AB21: FOLIO | AC21: MONTO | AD21: FECHA | AE21: FOLIO | AF21: MONTO | AG21: FECHA | AH21: FOLIO | AI21: MONTO | AJ21: FECHA | AK21: FOLIO | AL21: MONTO | AM21: FECHA | AN21: FOLIO
D22: =D8 -> DANAE GARCÍA JIMÉNEZ | H22: 1995 | I22: 45904 | J22: TC | K22: 1995 | L22: 45933 | M22: 8.5907785e+16 | N22: 1995 | O22: 45966 | P22: 8.5901977e+16 | Q22: 1995 | R22: 45996 | S22: 95876545 | T22: 1995 | U22: 46027 | V22: 8.5907935e+16 | W22: 1995 | X22: 45993 | Y22: 8.5902321e+16 | Z22: 1995 | AA22: 46057 | AB22: 8.5907053e+16 | AC22: 1995 | AD22: 46066 | AE22: 8.5903656e+16 | AF22: 1995 | AG22: 46099 | AH22: 8.5906685e+16 | AI22: 1995 | AJ22: 46146 | AK22: 960913 | AL22: 1995 | AM22: 46176 | AN22: 560315466 | AO22: fact ok
D23: =D9 -> SARA ANALI CRUZ PORTILLA | H23: 1995 | I23: 45903 | J23: 85909084190324600´ | K23: 1995 | L23: 45935 | M23: KLAR OP | N23: 1995 | O23: 45966 | P23: 8.5902277e+16 | Q23: 1995 | R23: 45996 | S23: 8.5909043e+16 | T23: 1995 | U23: 46083 | V23: 8948427 | Z23: 1995 | AA23: 46098 | AB23: 8.5906251e+16 | AC23: 1995 | AD23: 46098 | AE23: 8.5906251e+16 | AF23: 1995 | AG23: 46116 | AH23: 8.5900882e+16 | AI23: 1995 | AJ23: 46116 | AK23: 8.5900882e+16 | AL23: 2395 | AM23: 46182 | AN23: 70466355 | AO23: fact ok
D24: =D10 -> JOHANA CRUZ MURGIA | H24: 2223 | I24: 45905 | J24: SF | K24: 2223 | L24: 45935 | M24: SF | N24: 2223 | O24: 45966 | P24: 644668 | Q24: 2223 | R24: 45995 | S24: 37195
D25: =D12 -> AITANA REBECA FERNÁNDEZ CRUZ | H25: 1995 | I25: 45905 | J25: 1375789930 | K25: 1995 | L25: 45934 | M25: 1470769624 | N25: 1995 | O25: 45964 | P25: 1595590764 | Q25: 1995 | R25: 45997 | S25: 61225 | T25: 1995 | U25: 46026 | V25: 1401261 | Z25: 1995 | AA25: 46056 | AB25: 302262 | AC25: 1995 | AD25: 46105 | AE25: 2403260 | AF25: 1995 | AG25: 46124 | AH25: 55332306 | AI25: 1995 | AJ25: 46154 | AK25: 120526 | AL25: 1995 | AM25: 46174 | AN25: 253194906 | AO25: no fact

Sheet 3°K
F1: Centro de Investigación Educativa Colegio San Diego | S1: ACEPTADOS POR CORPORATIVO
F2: Punta el Campanario #183 Col. Bahia de San Martín CP 96536 | S2: PAGOS DE HIJOS DE MAESTROS
F3: PREESCOLAR 30PJN1037Z PRIMARIA 30PPR3773B SECUNDARIA 30PES0033G | S3: MES PAGADO
D4: FACTURA | F4: CICLO ESCOLAR 2024-2025 | S4: ALUMNO DADO DE BAJA
B7: N° | C7: MATRICULA | D7: NOMBRE DEL ALUMNO | E7: PROMOCION | F7: INSCRIPCION | G7: FOLIO | H7: FECHA | I7: MATERIAL | J7: FECHA | K7: FOLIO | L7: ARANCEL | M7: FECHA | N7: FOLIO | O7: LIBROS | P7: FECHA | Q7: FOLIO | R7: UNIFORMES | S7: FECHA | T7: FOLIO | U7: PLAN PAGO | V7: BECA | W7: COLEG | X7: TOTAL | Y7: 10 meses
A8: 921 272 1703 | C8: REINSCRIPCIÓN | D8: CARLA SOFÍA JIMÉNEZ CRUZ | E8: NOVIEMBRE-DICIEMBRE | F8: 1450 | G8: 4667997 | H8: 45677 | Y8: =+X8/12 -> 0
A9: 921 280 7541 | C9: NUEVO INGRESO | D9: ELISA ABIGAIL ALONSO ZAMORA | E9: ENERO FEBRERO | F9: 1450 | G9: 8439639819 | H9: 45701 | I9: 2990 | J9: 45701 | K9: 8439639819 | L9: 2390 | M9: 45701 | N9: 8439639819 | O9: 3900 | P9: 45797 | Q9: 7218123 | R9: 3085 | S9: 45894 | T9: 3520740 | U9: 10 MESES | V9: 0.3 | W9: 2990 | X9: 2394
C10: REINSCRIPCIÓN | D10: NAYAN MARIN MARTINEZ | E10: ENERO FEBRERO | F10: 1450 | G10: HSBC522914 | H10: 45723 | I10: 2990 | J10: 45723 | K10: HSBC522914 | L10: 2390 | M10: 45723 | N10: HSBC522914 | O10: 3900 | P10: 45796 | Q10: 4076892 | U10: 10 MESES | V10: 0.25 | W10: 3420 | X10: 2565
A11: 921 229 2822 | C11: REINSCRIPCIÓN | D11: KAI DE MARIA HERNADEZ ROMÁN | E11: ENERO FEBRERO | F11: 1450 | G11: 12561756 | H11: 45877 | I11: 1212 | J11: 45964 | K11: 1592829844 | U11: 10 MESES | V11: 0.3 | W11: 2990 | X11: 2394
K12: x
B19: COLEGIATURA
B20: N° | C20: MATRICULA | D20: NOMBRE DEL ALUMNO | E20: AGOSTO | H20: SEPTIEMBRE | K20: OCTUBRE | N20: NOVIEMBRE | Q20: DICIEMBRE | T20: ENERO | W20: JULIO | Z20: FEBRERO | AC20: MARZO | AF20: ABRIL | AI20: MAYO | AL20: JUNIO
E21: MONTO | F21: FECHA | G21: FOLIO | H21: MONTO | I21: FECHA | J21: FOLIO | K21: MONTO | L21: FECHA | M21: FOLIO | N21: MONTO | O21: FECHA | P21: FOLIO | Q21: MONTO | R21: FECHA | S21: FOLIO | T21: MONTO | U21: FECHA | V21: FOLIO | W21: MONTO | X21: FECHA | Y21: FOLIO | Z21: MONTO | AA21: FECHA | AB21: FOLIO | AC21: MONTO | AD21: FECHA | AE21: FOLIO | AF21: MONTO | AG21: FECHA | AH21: FOLIO | AI21: MONTO | AJ21: FECHA | AK21: FOLIO | AL21: MONTO | AM21: FECHA | AN21: FOLIO
C22: PASO PAPA | D22: =D8 -> CARLA SOFÍA JIMÉNEZ CRUZ | H22: 2052 | I22: 45936 | J22: 1768637 | K22: 2052 | L22: 45936 | M22: 89705632 | N22: 2052 | O22: 46067 | P22: 5478962135 | Q22: 2052 | R22: 46067 | S22: 5478962135 | T22: 2052 | U22: 46067 | V22: 5478962135 | Z22: 2052 | AA22: 46067 | AB22: 5478962135 | AC22: 2052 | AD22: 46149 | AE22: 64046 TD | AI22: 2452 | AJ22: 46155 | AK22: 7098753
D23: =D9 -> ELISA ABIGAIL ALONSO ZAMORA | H23: 2394 | I23: 45904 | J23: 92025 | K23: 2394 | L23: 45932 | M23: 370251314 | N23: 2394 | O23: 45966 | P23: 1097424 | Q23: 2394 | R23: 45994 | S23: 8847032 | T23: 2394 | U23: 46034 | V23: 2989580 | W23: 2394 | X23: 46000 | Y23: 5611616 | Z23: 2394 | AA23: 46057 | AB23: 6014650 | AC23: 2394 | AD23: 46083 | AE23: 7016241 | AF23: 2394 | AG23: 46113 | AH23: 48302093 | AI23: 2394 | AJ23: 46148 | AK23: 6567541 | AL23: 2394 | AM23: 46175 | AN23: 99599832 | AO23: fact ok
D24: =D10 -> NAYAN MARIN MARTINEZ | H24: 2565 | I24: 45866 | J24: 9359986 | K24: 2565 | L24: 45866 | M24: 9359986 | N24: 2565 | O24: 45949 | P24: 5345598 | Q24: 2565 | R24: 45996 | S24: 4301107 | T24: 2565 | U24: 46028 | V24: 590013 | Z24: 2565 | AA24: 46081 | AB24: 6760150 | AC24: 2565 | AD24: 46096 | AE24: 6656463 | AF24: 2565 | AG24: 46108 | AH24: 9111778 | AI24: 2565 | AJ24: 46140 | AK24: 9959550 | AL24: 2565 | AM24: 46158 | AN24: 1341080 | AO24: fact ok
D25: KAI DE MARIA HERNANDEZ ROMAN | H25: 2794 | I25: 45905 | J25: 1592829844 | K25: 2794 | L25: 45936 | M25: 1592829844 | N25: 2794 | O25: 45964 | P25: 1592829844 | Q25: 2794 | R25: 45964 | S25: 1592829844 | T25: 3194 | U25: 46057 | V25: 4589763122 | Z25: 3174 | AA25: 46100 | AB25: 83057999 | AC25: 3190 | AD25: 46147 | AE25: 54733770 | AF25: 3190 | AG25: 46147 | AH25: 54733770 | AO25: 6380

Sheet 1°P
F1: Centro de Investigación Educativa Colegio San Diego | S1: ACEPTADOS POR CORPORATIVO
F2: Punta el Campanario #183 Col. Bahia de San Martín CP 96536 | S2: PAGOS DE HIJOS DE MAESTROS
F3: PREESCOLAR 30PJN1037Z PRIMARIA 30PPR3773B SECUNDARIA 30PES0033G | S3: MES PAGADO
D4: FACTURA | F4: CICLO ESCOLAR 2024-2025 | S4: ALUMNO DADO DE BAJA
B7: N° | C7: MATRICULA | D7: NOMBRE DEL ALUMNO | E7: PROMOCION | F7: INSCRIPCION | G7: FOLIO | H7: FECHA | I7: MATERIAL | J7: FECHA | K7: FOLIO | L7: ARANCEL | M7: FECHA | N7: FOLIO | O7: LIBROS | P7: FECHA | Q7: FOLIO | R7: UNIFORMES | S7: FECHA | T7: FOLIO | U7: PLAN PAGO | V7: BECA | W7: COLEG | X7: TOTAL
A8: 921 129 3915 | B8: REINSCRIPCIÓN | D8: GUTIERREZ VEGA JAZMIN ALEJANDRA | E8: NOVIEMBRE-DICIEMBRE | F8: GRATIS | G8: GRATIS | H8: GRATIS | I8: 2690 | J8: 45656 | K8: 8.5902114e+16 | L8: 2490 | M8: 45656 | N8: 8.5902114e+16 | O8: 5500 | P8: 45805 | Q8: 8.5903082e+16
A9: 921 266 3787 | B9: REINSCRIPCIÓN | D9: LIAM SAEL RAMIREZ PEREA | E9: NOVIEMBRE-DICIEMBRE | F9: GRATIS | G9: GRATIS | H9: GRATIS | I9: 2690 | J9: 45645 | K9: 8.590208e+16 | L9: 2490 | M9: 45645 | N9: 8.590208e+16 | O9: 5500 | P9: 45808 | Q9: 8.5900908e+16
A10: 921 178 7512 | B10: NUEVO INGRESO | D10: ISABELLA GALVEZ DÍAZ | E10: NOVIEMBRE-DICIEMBRE | F10: GRATIS | G10: GRATIS | H10: GRATIS | I10: 2690 | J10: 45675 | K10: 6192027242 | L10: 2490 | M10: 45675 | N10: 6192027242 | O10: 5500 | P10: 45797 | Q10: 6729893681 | R10: 3085 | S10: 45896 | T10: SF | U10: 10 MESES | V10: 0.25 | W10: 3838.8 | X10: 2879
A11: 921 151 7779 | B11: NUEVO INGRESO | D11: GEORGINA FERNÁNDEZ THEUREL | E11: NOVIEMBRE-DICIEMBRE | F11: GRATIS | G11: GRATIS | H11: 0 | I11: 2690 | J11: 45874 | K11: 8.5901285e+16 | L11: 2490 | M11: 45678 | N11: 8.5905809e+16 | O11: 5500 | P11: 45819 | Q11: 8.5902439e+16 | R11: 3085 | T11: SF | U11: 12 MESES | V11: 0.25 | W11: 3199 | X11: 2399
A12: 803 949 5281 | B12: REINSCRIPCIÓN | D12: YOSHIMI MADARA BURELO OLIVARES | E12: ENERO-FEBRERO | F12: GRATIS | G12: GRATIS | H12: 45719 | I12: 2690 | L12: 2490 | M12: 45719 | N12: 772948 | O12: 5500 | P12: 45798 | Q12: 30828 | U12: 12 MESES | V12: 0.25 | W12: 3199 | X12: 2399
A13: 921 265 1701 | B13: NUEVO INGRESO | D13: LILIAN RENATA CORTEZ FUENTES | E13: ENERO-FEBRERO | F13: GRATIS | G13: GRATIS | H13: 45719 | L13: 2490 | M13: 45719 | N13: 303251 | O13: 4000 | P13: 45904 | Q13: 89428950 | U13: 12 MESES | V13: 0.3 | W13: 3199 | X13: 2239
A14: 921 195 6663 | B14: NUEVO INGRESO | C14: ENVIAR COMPROBANTE DE PAGO EN PDF | D14: EITHAN GARDUZA SCOTT | E14: ENERO-FEBRERO | F14: GRATIS | G14: GRATIS | H14: 45723 | I14: 2690 | J14: 45723 | K14: 104452928362 | L14: 2490 | M14: 45723 | N14: 104452928632
A15: 921 121 3656 | B15: NUEVO INGRESO | D15: LIAM ZAMORANO HERNANDEZ | E15: MARZO-JUNIO | F15: GRATIS | G15: GRATIS | H15: GRATIS | I15: 2690 | J15: 45827 | K15: 24310 | L15: 2490 | M15: 45827 | N15: 24310 | U15: 12 MESES | V15: 0.2 | W15: 3199 | X15: 2559
A16: 921 150 2316 | B16: NUEVO INGRESO | D16: REGINA PEREYRA TOLEDO | E16: MARZO-JUNIO | F16: GRATIS | G16: GRATIS | H16: GRATIS | I16: 2690 | J16: 45838 | K16: 8.5903861e+16 | L16: 2490 | M16: 45838 | N16: 8.5903861e+16 | O16: 5900 | P16: 45859 | Q16: 8.5902092e+16 | U16: 12 MESES | V16: 0.18 | W16: 3199.9 | X16: 2623
A17: 921 144 6840 | B17: NUEVO INGRESO | D17: ABRAHAM DE JESUS MONTERO GARCIA | E17: NOVIEMBRE-DICIEMBRE | F17: GRATIS | G17: GRATIS | H17: GRATIS | I17: 1500 | J17: 45743 | K17: 2065526638 | L17: 1500 | M17: 45846 | N17: 18870727 | O17: 5900 | P17: 45877 | Q17: 93322540 | R17: 2000 | S17: 45884 | T17: 67780840 | U17: 12 MESES | W17: 3199 | X17: 1500
A18: 923 130 6307 | B18: NUEVO INGRESO | C18: SIMON BOLIVAR | D18: IVANNA GARCIA RUIZ | E18: MARZO-JUNIO | F18: GRATIS | G18: GRATIS | H18: GRATIS | L18: 1743 | M18: 45861 | N18: 59269061 | O18: 5900 | P18: 45888 | Q18: 12415877 | R18: 3085 | S18: 45888 | T18: 12415877 | U18: 10 MESES | X18: 2687
A19: 921 307 0216 | B19: REINSCRIPCIÓN | C19: PROMO 2X1 | D19: MATIAS SAUL RIVAS GRAJEDA | E19: MARZO-JUNIO | F19: GRATIS | G19: GRATIS | H19: 45872 | L19: 2499 | M19: 45885 | N19: 4358446906
A20: 921 196 0028 | B20: NUEVO INGRESO | C20: MAESTRA CSD | D20: AKANE MORALES ROMAN | E20: MARZO-JUNIO | F20: GRATIS | G20: GRATIS | H20: 45877 | I20: 1345 | J20: 45877 | K20: SF | L20: 1245 | M20: 45877 | N20: sf | O20: 3200 | P20: 45937 | Q20: 50995809 | R20: 3208.4 | S20: 45880 | T20: 927278 | U20: 12 MESES | V20: 0.5 | W20: 3199 | X20: 1559
A21: 921 261 1498 | B21: REINSCRIPCIÓN | D21: KHATERIN AMAIA MORALES DOMINGUEZ | E21: MARZO-JUNIO | F21: GRATIS | G21: GRATIS | H21: 45896 | I21: 2690 | J21: 45896 | K21: 5301872915 | L21: 2490 | M21: 45896 | N21: 5301872915
A22: 961 300 0674 | B22: REINSCRIPCIÓN | D22: YELENA ROSAS SANCHEZ | E22: . | F22: GRATIS | G22: GRATIS | H22: 3.875 | I22: 1345 | J22: 45900 | K22: SF | L22: 1245 | M22: 45900 | N22: SF | U22: 10 MESES | V22: 0.3 | X22: 2687
B27: COLEGIATURA
B28: N° | C28: MATRICULA | D28: NOMBRE DEL ALUMNO | E28: AGOSTO | H28: SEPTIEMBRE | K28: OCTUBRE | N28: NOVIEMBRE | Q28: DICIEMBRE | T28: ENERO | W28: JULIO | Z28: FEBRERO | AC28: MARZO | AF28: ABRIL | AI28: MAYO | AL28: JUNIO
E29: MONTO | F29: FECHA | G29: FOLIO | H29: MONTO | I29: FECHA | J29: FOLIO | K29: MONTO | L29: FECHA | M29: FOLIO | N29: MONTO | O29: FECHA | P29: FOLIO | Q29: MONTO | R29: FECHA | S29: FOLIO | T29: MONTO | U29: FECHA | V29: FOLIO | W29: MONTO | X29: FECHA | Y29: FOLIO | Z29: MONTO | AA29: FECHA | AB29: FOLIO | AC29: MONTO | AD29: FECHA | AE29: FOLIO | AF29: MONTO | AG29: FECHA | AH29: FOLIO | AI29: MONTO | AJ29: FECHA | AK29: FOLIO | AL29: MONTO | AM29: FECHA | AN29: FOLIO
D30: =D8 -> GUTIERREZ VEGA JAZMIN ALEJANDRA | H30: 2687 | I30: 45903 | J30: 43606205 | K30: 2687 | L30: 45932 | M30: 3820081 | N30: 2673 | O30: 45931 | P30: 3820081 | Q30: 2673 | R30: 45995 | S30: 36193672 | T30: 2673 | U30: 46027 | V30: 78923078 | Z30: 2673 | AA30: 46057 | AB30: 8822285 | AC30: 2673 | AD30: 46086 | AE30: 99922069 | AF30: 2677 | AG30: 46115 | AH30: 79836391 | AI30: 2673 | AJ30: 46147 | AK30: 52361928 | AL30: 2673 | AM30: 46174 | AN30: 51920061 | AO30: no fact
D31: =D9 -> LIAM SAEL RAMIREZ PEREA | E31: 2623 | F31: 45874 | G31: 8.5902155e+16 | H31: 2623 | I31: 45905 | J31: 8.5904182e+16 | K31: 2623 | L31: 45935 | M31: 853216 | N31: 2623 | O31: 45964 | P31: 8.5906925e+16 | Q31: 2623 | R31: 45993 | S31: 8.5901155e+16 | T31: 2623 | U31: 46025 | V31: 579069 | W31: 2623 | X31: 45999 | Y31: 8.5904697e+16 | Z31: 2623 | AA31: 46057 | AB31: 8.5906126e+16 | AC31: 2623 | AD31: 46085 | AE31: 2603954306300 | AF31: 2623 | AG31: 46115 | AH31: 8.5900297e+16 | AI31: 2624 | AJ31: 46146 | AK31: 312464 | AL31: 2623 | AM31: 46175 | AN31: 315361 | AO31: fact ok
C32: FACTURA | D32: =D10 -> ISABELLA GALVEZ DÍAZ | H32: 2879 | I32: 45675 | J32: 6192027242 | K32: 2879 | L32: 45931 | M32: 1144620 | N32: 2879 | O32: 45964 | P32: 44999439 | Q32: 2879 | R32: 45992 | S32: 86276026 | T32: 2879 | U32: 46027 | V32: 24191315 | Z32: 2879 | AA32: 46057 | AB32: 73490873 | AC32: 2879 | AD32: 46082 | AE32: 82745502 | AF32: 2879 | AG32: 46116 | AH32: 82180340 | AI32: 2879 | AJ32: 46147 | AK32: 86097863 | AL32: 2879 | AM32: 46175 | AN32: 5788308 | AO32: fact ok
D33: =D11 -> GEORGINA FERNÁNDEZ THEUREL | E33: 2399 | F33: 45874 | G33: 8.5901285e+16 | H33: 2399 | I33: 45903 | J33: 250370 | K33: 2399 | L33: 45936 | M33: 8.5902762e+16 | N33: 2399 | O33: 45966 | P33: 8.5907127e+16 | Q33: 2399 | R33: 45999 | S33: 8.5902882e+16 | T33: 2399 | U33: 46029 | V33: 8.5902268e+16 | Z33: 2399 | AA33: 46057 | AB33: 8.5907633e+16 | AC33: 2399 | AD33: 46105 | AE33: 1061928 | AF33: 2399 | AG33: 46105 | AH33: 1061928 | AI33: 2399 | AJ33: 46148 | AK33: 312665
B34: 10 MESES | C34: NO FACTURA | D34: =D12 -> YOSHIMI MADARA BURELO OLIVARES | H34: 2399 | I34: 45901 | J34: DEBIT CARD | K34: 2399 | L34: 45935 | M34: 656567 | N34: 2399 | O34: 45966 | P34: 24952 | Q34: 2399 | R34: 45996 | S34: 55487960 | T34: 2799 | U34: 46036 | V34: PAGOTDINT | Z34: 2399 | AA34: 46058 | AB34: 305688 | AC34: 2399 | AD34: 46086 | AE34: 87985645 | AF34: 2799 | AG34: 46124 | AH34: 548976213 | AI34: 2399 | AJ34: 46148 | AK34: 288 (tarjeta) | AL34: 2399 | AM34: 46175 | AN34: 872251 TD | AO34: no fact
D35: =D13 -> LILIAN RENATA CORTEZ FUENTES | H35: 2879 | I35: 45901 | J35: 16908756 | K35: 2239 | L35: 45905 | M35: 80059121 | N35: 2239 | O35: 45967 | P35: 38642635 | Q35: 2239 | R35: 45999 | S35: 38646235 | T35: 2239 | U35: 45999 | V35: deb0534 | W35: 2239 | X35: 46000 | Y35: deb0534 | Z35: 2239 | AA35: 46057 | AB35: 6604664 | AC35: 2239 | AD35: 46115 | AE35: 6604664 | AF35: 2239 | AG35: 46116 | AH35: 6604664 | AI35: 2239 | AJ35: 46147 | AK35: 6604664 | AL35: 1839 | AM35: 46181 | AN35: 906847 | AO35: no fact | AP35: comenta: Buenos días le comenté a la directora que no me a completaba para el pago de colegiatura
D36: =D14 -> EITHAN GARDUZA SCOTT
D37: =D15 -> LIAM ZAMORANO HERNANDEZ | E37: 2559 | F37: 45874 | G37: 84695 | H37: 2559 | I37: 45905 | J37: 93487 | K37: 2559 | L37: 45933 | M37: 332114 | N37: 2559 | O37: 45966 | P37: 10876 | Q37: 2239 | R37: 45999 | S37: 64705 | T37: 2559 | U37: 5 | V37: 9463952 | W37: 2239 | X37: 45999 | Y37: 64705 | Z37: 2639 | AA37: 46062 | AB37: 62670 | AC37: 2639 | AD37: 46086 | AE37: 879512 | AF37: 2639 | AG37: 46117 | AH37: 61069 | AI37: 2639 | AJ37: 46146 | AK37: 286 (tarjeta) | AL37: 2559 | AM37: 46181 | AN37: 84865 TC | AO37: no fact
D38: =D16 -> REGINA PEREYRA TOLEDO | E38: 2623 | F38: 45781 | G38: 348350 | H38: 2623 | I38: 45902 | J38: 8.5901635e+16 | K38: 2623 | L38: 45932 | M38: 8.5900823e+15 | N38: 2623 | O38: 45964 | P38: 8.5906491e+16 | Q38: 2623 | R38: 45992 | S38: 8.5905111e+16 | T38: 2623 | U38: 46027 | V38: 8.5904815e+16 | W38: 2623 | X38: 45992 | Y38: 8.5905111e+16 | Z38: 2623 | AA38: 46058 | AB38: 8.590141e+16 | AC38: 2623 | AD38: 46085 | AE38: 771274306369 | AF38: 2623 | AG38: 46126 | AH38: 140426 | AI38: 2623 | AJ38: 46156 | AK38: 414313463 | AL38: 2623 | AM38: 46174 | AN38: 315263 | AO38: fact ok
D39: =D17 -> ABRAHAM DE JESUS MONTERO GARCIA | E39: 1500 | F39: 45901 | G39: 43551496 | H39: 1500 | I39: 45905 | J39: 50897645 | K39: 1900 | L39: 45951 | M39: 59097254 | N39: 1500 | O39: 45952 | P39: 59097254 | Q39: 1500 | R39: 46005 | S39: 20189863 | T39: 1500 | U39: 46027 | V39: 46143963 | W39: 1500 | X39: 45999 | Y39: 536590 | Z39: 1500 | AA39: 46053 | AB39: 5434853 | AC39: 1500 | AD39: 46079 | AE39: 97852712 | AF39: 1500 | AG39: 46108 | AH39: 74182179 | AI39: 1500 | AJ39: 46141 | AK39: 32477095 | AL39: 1500 | AM39: 46174 | AN39: 42349957 | AO39: fact ok
D40: =D18 -> IVANNA GARCIA RUIZ | H40: 2687 | I40: 45905 | J40: SF | K40: 2687 | L40: 45935 | M40: 44449845 | N40: 2687 | O40: 45966 | P40: 37240654 | Q40: 2687 | R40: 45993 | S40: 25782987 | T40: 2687 | U40: 46027 | V40: 36804787 | Z40: 2687 | AA40: 46056 | AB40: 66317447 | AC40: 2687 | AD40: 46083 | AE40: 3915390 | AF40: 2687 | AG40: 46108 | AH40: 88341480 | AI40: 2687 | AJ40: 46139 | AK40: 84625200 | AL40: 2687 | AM40: 46168 | AN40: 49090922 | AO40: fact ok
D41: =D19 -> MATIAS SAUL RIVAS GRAJEDA | H41: 2686 | I41: 45877 | J41: 86337846 | K41: 2686 | L41: 45936 | M41: 67398754 | N41: 2686 | O41: 45967 | P41: 1410671778 | Q41: 2686 | R41: 45997 | S41: 48526973 | T41: 2686 | U41: 46028 | V41: 21536479 | Z41: 2686 | AA41: 46063 | AB41: 67398754 | AC41: 2686 | AD41: 46088 | AE41: 58936336 | AF41: 2687 | AG41: 46156 | AH41: 58639034 | AI41: 2686 | AJ41: 46147 | AK41: 67398754 | AL41: 2686 | AM41: 46177 | AN41: 91470328 | AO41: fact ok
D42: =D20 -> AKANE MORALES ROMAN | H42: 1599 | I42: 45905 | J42: 38846348 | K42: 1600 | L42: 45937 | M42: 50995809 | N42: 1599 | O42: 45962 | P42: 3415019 | Q42: 1599 | R42: 45996 | S42: TRANSFDE | T42: 1599 | U42: 46361 | V42: TRANSFDE | Z42: 1559 | AA42: 46058 | AB42: TRANSFDE | AC42: 1559 | AD42: 46086 | AE42: TRANSFDE | AF42: 1559 | AG42: 46118 | AH42: 26603543 | AI42: 1559 | AJ42: 46147 | AK42: 49458601 | AL42: 1599 | AM42: 46174 | AN42: 126527 TD | AO42: no fact
D43: KHATERIN AMAIA MORALES DOMINGUEZ | H43: 2879 | I43: 45905 | J43: 89966780 | K43: 3147 | L43: 45934 | M43: 24876531 | N43: 3147 | O43: 45967 | P43: 50679516 | Q43: 3147 | R43: 46361 | S43: 71292800 | T43: 3147 | U43: 46058 | V43: 83006103 | Z43: 3147 | AA43: 46177 | AB43: 44804264 | AC43: 3147 | AD43: 46086 | AE43: 465 | AF43: 3547 | AG43: 46181 | AH43: 86330335 | AI43: 3147 | AJ43: 46147 | AK43: 44604939 | AN43: convenio
D44: YELENA ROSAS SANCHEZ | H44: 2686 | I44: 45934 | J44: 48902654 | K44: 2686 | L44: 45944 | M44: YTMBOK | N44: 2686 | O44: 45966 | P44: 974643 | Q44: 2686 | R44: 45995 | S44: V8WF3G | T44: 2686 | U44: 46027 | V44: TC | Z44: 2239 | AA44: 46054 | AB44: CTA2493 | AC44: 2239 | AD44: 46086 | AE44: CTA2493 | AF44: 2839 | AG44: 46129 | AH44: 573084 | AI44: 2239 | AJ44: 46150 | AK44: 10333 TC | AL44: 2239 | AM44: 46188 | AN44: 0349 TD | AO44: no fact
C45: NO LOC NUMERO | D45: JARA DOMINGUEZ MARIA RENATA | T45: 2559 | U45: 46040 | V45: 54621387 | Z45: 2559 | AA45: 46058 | AB45: 39434 | AC45: 2559 | AD45: 46086 | AE45: 25489671 | AF45: 2559 | AG45: 46115 | AH45: HSB5682276 | AI45: =2559+400 -> 2959 | AJ45: 46153 | AK45: 110526 | AL45: 2959 | AM45: 46199 | AN45: 54758 | AO45: no fact
N52: 380
...

Sheet 2°P
F1: Centro de Investigación Educativa Colegio San Diego | S1: ACEPTADOS POR CORPORATIVO
F2: Punta el Campanario #183 Col. Bahia de San Martín CP 96536 | S2: PAGOS DE HIJOS DE MAESTROS
F3: PREESCOLAR 30PJN1037Z PRIMARIA 30PPR3773B SECUNDARIA 30PES0033G | S3: MES PAGADO
D4: FACTURA | F4: CICLO ESCOLAR 2024-2025 | S4: ALUMNO DADO DE BAJA
B7: N° | C7: MATRICULA | D7: NOMBRE DEL ALUMNO | E7: PROMOCION | F7: INSCRIPCION | G7: FOLIO | H7: FECHA | I7: MATERIAL | J7: FECHA | K7: FOLIO | L7: ARANCEL | M7: FECHA | N7: FOLIO | O7: LIBROS | P7: FECHA | Q7: FOLIO | R7: UNIFORMES | S7: FECHA | T7: FOLIO | U7: PLAN PAGO | V7: BECA | W7: COLEG | X7: TOTAL
A8: 294 121 5790 | B8: REINSCRIPCIÓN | D8: OSWALDO LOPEZ FONSECA | E8: NOVIEMBRE-DICIEMBRE | F8: 1550 | G8: 1343589496 | H8: 45619 | I8: 2690 | J8: 45809 | K8: 7762010280 | L8: 1810 | M8: 45809 | N8: 7762010280 | O8: 5500 | P8: 45811 | Q8: 7762010280
A9: 33 1252 9236 | B9: REINSCRIPCIÓN | D9: CARLOS DANIEL TRUJILLO RODRIGUEZ | E9: NOVIEMBRE-DICIEMBRE | F9: 1550 | G9: 2813342240 | H9: 45636 | I9: 2690 | J9: 45636 | K9: 2813452941 | L9: 2490 | M9: 45636 | N9: 2813386375 | O9: 5500 | P9: 45797 | Q9: 6736479464
A10: 921 151 3220 | B10: REINSCRIPCIÓN | D10: CESAR BENHUR CASTAN OVANDO | E10: NOVIEMBRE-DICIEMBRE | F10: 1550 | G10: 85902131894335200´ | H10: 45643 | I10: 2690 | J10: 45810 | K10: 8.5905633e+16 | L10: 2490 | M10: 45810 | N10: 8.5905633e+16 | O10: 5500 | P10: 45792 | Q10: 8.5904168e+16 | U10: 10 MESES | V10: 0.25 | W10: 3838 | X10: 2879
A11: 921 207 3167 | B11: REINSCRIPCIÓN | D11: JONATHAN DE JESÚS SALINAS TOLEDO | E11: NOVIEMBRE-DICIEMBRE | F11: 1550 | G11: 287318 | H11: 45657 | I11: 2690 | J11: 45889 | K11: 164200 | O11: 5900 | P11: 45900 | Q11: 310825 | U11: 10 MESES | V11: 0.3 | W11: 3838 | X11: 2686
A12: 921 272 1703 | B12: REINSCRIPCIÓN | D12: NATHALIA ITZAÉ JIMÉNEZ CRUZ | E12: NOVIEMBRE-DICIEMBRE | F12: 1550 | G12: 8127769 | H12: 45677
A13: 921 103 2088 | B13: REINSCRIPCIÓN | C13: 20% DESCUENTO ARANCEL | D13: JEAN CARLOS RICARDEZ VEGA | E13: ENERO-FEBRERO | F13: 1550 | G13: 7328700925 | H13: 45688 | I13: 2690 | J13: 45905 | K13: 572893 | L13: 2490 | M13: 45905 | N13: 572893 | U13: 12 MESES | V13: 0.3 | W13: 3199 | X13: 2239
A14: 921 205 6342 | B14: REINSCRIPCIÓN | C14: 20% DESCUENTO ARANCEL | D14: DOMINIC GUSTAVO NIVON OROZCO | E14: ENERO-FEBRERO | F14: 1550 | G14: 8.5904684e+16 | H14: 45694 | I14: 2690 | J14: 45895 | K14: 332872 | L14: 2490 | M14: 45895 | N14: 332872 | U14: 12 MESES | V14: 0.2 | W14: 3199 | X14: 2559
A15: 921 122 6826 | B15: REINSCRIPCIÓN | D15: LUIS MARIO HERNANDEZ VARGAS | E15: ENERO-FEBRERO | F15: 1550 | G15: HSBC343677 | H15: 45716 | I15: 2690 | J15: 45866 | K15: 1538958 | L15: 1992 | M15: 45866 | N15: 4029199 | O15: 5900 | P15: 45869 | Q15: 281018
A16: 921 115 9794 | B16: REINSCRIPCIÓN | D16: ROMINA RODRIGUEZ PEREZ | E16: ENERO-FEBRERO | F16: 1550 | G16: 9741630351 | H16: 45716 | I16: 2690 | J16: 45895 | K16: 85906073290323800´ | L16: 2490 | M16: 45895 | N16: 85906073290323800´ | O16: 5900 | P16: 45895 | Q16: 85906073290323800´ | U16: 10 MESES | V16: 0.25 | W16: 3838.8 | X16: 2879
A17: 921 291 0428 | B17: REINSCRIPCIÓN | D17: JOSE MIGUEL CRUZ LOPEZ | E17: MARZO-ABRIL | F17: 1550 | G17: 2998534748 | H17: 45754 | I17: 1234 | J17: 45825 | K17: 63415250 | O17: 2655 | P17: 45903 | Q17: 3012346
A18: 921 105 3439 | B18: NUEVO INGRESO | D18: INGRID PATRICIA GUZMAN SANTIAGO | E18: MARZO-ABRIL | F18: PENDIENTE | G18: PENDIENTE | H18: PENDIENTE | I18: 2690 | J18: 45838 | K18: 48635063 | L18: 2490 | M18: 45793 | N18: 6378639052 | O18: 5900 | P18: 45861 | Q18: 14374475 | U18: 12 MESES | V18: 0.2 | W18: 3838.8 | X18: 2559
A19: 921 178 1586 | B19: SIMON BOLIVAR | C19: 30% DESC ARANCEL Y MATERIAL | D19: EMMA SOFIA DOMINGUEZ NIETO | E19: MARZO-JUNIO | F19: GRATIS | G19: GRATIS | H19: 45869 | I19: 1883 | J19: 45869 | K19: 27027325 | L19: 1743 | M19: 45869 | N19: 30996518 | O19: 5900 | P19: 45871 | Q19: 27816400 | R19: 3085 | S19: 45871 | T19: 19765211 | U19: 10 MESE | V19: 0.3 | W19: 3838 | X19: 2878
A20: 921 272 5928/9212286982 | B20: REINSCRIPCIÓN | C20: INSCRIPCIÓN GRATIS | D20: VALENTINA TOSCANO MOSQUEDA | E20: MARZO-JUNIO | F20: GRATIS | G20: GRATIS | H20: 45883 | I20: 2690 | J20: 45883 | K20: 743269432 | L20: 2490 | M20: 45883 | N20: 743269432 | O20: 3000 | P20: 45883 | Q20: 743269432 | U20: 10 MESES | V20: 0.25 | W20: 3838 | X20: 2878
A21: 921 118 1360 | B21: REINSCRIPCIÓN | D21: ANGEL DE JESUS ARRONIZ CALZADA | E21: MARZO-JUNIO | F21: 1860 | G21: 55270537 | H21: 45865 | I21: 2783 | J21: 45839 | K21: 2324992 | U21: 10 MESES | V21: 0.25 | W21: 3838 | X21: 2878
A22: 921 138 9951 | B22: REINSCRIPCIÓN | D22: ANDRES VEGA CAPORAL | E22: MARZO-JUNIO | F22: GRATIS | G22: GRATIS | H22: 45890 | I22: 2690 | J22: 45890 | K22: 91745108 | L22: 2490 | M22: 45901 | N22: 58428646 | O22: 3000 | P22: 45912 | Q22: 9120272 | U22: 10 MESES | V22: 0.18 | W22: 3838.8 | X22: 3147
A23: 922 140 6895 | B23: REINSCRIPCIÓN | C23: EL MARTES 26 HACE LOS PAGOS | D23: MATIAS ALEJANDRO PEREZ REYES | E23: MARZO-JUNIO | F23: GRATIS | G23: GRATIS | H23: 45898 | I23: 1345 | J23: 45898 | K23: 87801674 | L23: 1245 | M23: 45898 | N23: 87801674
A24: 921 125 2551 | B24: REINSCRIPCIÓN | D24: JARED ALEXANDER FUENTES TORRRES | E24: MARZO-JUNIO | F24: GRATIS | G24: GRATIS | H24: 45890 | I24: 1445 | J24: 45897 | K24: 681592 | L24: 1195 | M24: 45897 | N24: 681592 | O24: 3000 | P24: 45918 | Q24: 180925 | U24: 10 MESES | V24: 0.3 | W24: 3838 | X24: 2686
B25: NUEVO INGRESO | D25: VALENTINA MARTINEZ | E25: MARZO-JUNIO
A26: 55 1260 2277 | C26: NUEVO INGRESO | D26: DOMINIC ISAAR RUIZ GARZÓN | E26: ENERO-FEBRERO | F26: 1550 | G26: 46190675 | H26: 46056 | I26: 1445 | J26: 46056 | K26: 46190675 | L26: 1245 | M26: 46056 | N26: 46190675 | U26: 12 MESES | V26: 0.25 | W26: 3199 | X26: 2559
D27: MARIA RENATA | E27: ENERO-FEBRERO
B33: COLEGIATURA
B34: N° | C34: MATRICULA | D34: NOMBRE DEL ALUMNO | E34: AGOSTO | H34: SEPTIEMBRE | K34: OCTUBRE | N34: NOVIEMBRE | Q34: DICIEMBRE | T34: ENERO | W34: JULIO | Z34: FEBRERO | AC34: MARZO | AF34: ABRIL | AI34: MAYO | AL34: JUNIO
E35: MONTO | F35: FECHA | G35: FOLIO | H35: MONTO | I35: FECHA | J35: FOLIO | K35: MONTO | L35: FECHA | M35: FOLIO | N35: MONTO | O35: FECHA | P35: FOLIO | Q35: MONTO | R35: FECHA | S35: FOLIO | T35: MONTO | U35: FECHA | V35: FOLIO | W35: MONTO | X35: FECHA | Y35: FOLIO | Z35: MONTO | AA35: FECHA | AB35: FOLIO | AC35: MONTO | AD35: FECHA | AE35: FOLIO | AF35: MONTO | AG35: FECHA | AH35: FOLIO | AI35: MONTO | AJ35: FECHA | AK35: FOLIO | AL35: MONTO | AM35: FECHA | AN35: FOLIO
C36: 10 MESES | D36: =D8 -> OSWALDO LOPEZ FONSECA | H36: 2600 | I36: 45874 | J36: 95945829 | K36: 2600 | L36: 45874 | M36: 95945829 | N36: 2600 | O36: 45874 | P36: 95945829 | Q36: 2600 | R36: 45997 | S36: 4654 | T36: 2600 | U36: 45997 | V36: 4654 | Z36: 2600 | AA36: 46022 | AB36: SF | AC36: =500+1500+600 -> 2600 | AD36: 46125 | AE36: 7410 | AF36: 2600 | AG36: 46167 | AH36: SF | AI36: 800 | AJ36: 46167 | AK36: SF | AO36: =2600-800 -> 1800 | AP36: PEND SOL NVO PAGO
D37: =D9 -> CARLOS DANIEL TRUJILLO RODRIGUEZ | H37: 2686 | I37: 45782 | J37: 48922771 | K37: 2686 | L37: 45930 | M37: 62348679 | N37: 2686 | O37: 45960 | P37: 49834581 | Q37: 2686 | R37: 45993 | S37: 77361689 | T37: 2686 | U37: 45999 | V37: 89312066 | Z37: 2686 | AA37: 46056 | AB37: 57499353 | AC37: 2686 | AD37: 46086 | AE37: 50648220 | AF37: 2686 | AG37: 46115 | AH37: 26344497 | AI37: 2686 | AJ37: 46147 | AK37: 25992592 | AL37: 2686 | AM37: 46179 | AN37: 46351542 | AO37: FACT OK
D38: =D10 -> CESAR BENHUR CASTAN OVANDO | H38: 2686 | I38: 45904 | J38: 58497120 | K38: 2879 | L38: 45930 | M38: 8.5904615e+16 | N38: 2879 | O38: 45960 | P38: 84681 | Q38: 2879 | R38: 45979 | S38: 84681 | T38: 2879 | U38: 46006 | V38: 20612 | Z38: 2879 | AA38: 46058 | AB38: 89745631 | AC38: 2879 | AD38: 46086 | AE38: 78452163 | AF38: 2879 | AG38: 46126 | AH38: 85974631 | AI38: 2879 | AJ38: 45780 | AK38: 312361 | AL38: 2879 | AM38: 46174 | AN38: 85116 TD | AO38: FACT OK
D39: =D11 -> JONATHAN DE JESÚS SALINAS TOLEDO | H39: 2494.75 | I39: 45900 | J39: 300825 | K39: 2494.75 | L39: 45935 | M39: 61025 | N39: 2494.75 | O39: 45965 | P39: 1615258 | Q39: 2496 | R39: 46361 | S39: 191152 | T39: 2496 | U39: 46041 | V39: 28994436 | Z39: 2694.5 | AA39: 46084 | AB39: DEP BANC | AC39: 2694 | AD39: 46135 | AE39: 28677803 | AF39: 2694 | AG39: 46135 | AH39: 28677803 | AI39: 2694 | AJ39: 46147 | AK39: 88516315 | AL39: 2694 | AM39: 46178 | AN39: 59924705 | AO39: NO FACT
C40: PASO PAPA | D40: =D12 -> NATHALIA ITZAÉ JIMÉNEZ CRUZ | H40: 2302 | I40: 45906 | J40: 1768637 | K40: 2302 | L40: 45906 | M40: 89137465 | N40: 2302 | O40: 46055 | P40: TDC | Q40: 2302 | R40: 46055 | S40: TDC | T40: 2302 | U40: 46055 | V40: TDC | Z40: 2302 | AA40: 46055 | AB40: TDC | AC40: 2702 | AD40: 46169 | AE40: 64046 TD | AI40: 2702 | AJ40: 46155 | AK40: 7098753
D41: =D13 -> JEAN CARLOS RICARDEZ VEGA | E41: 2399 | F41: 45887 | G41: 6049483 | H41: 2399 | I41: 45905 | J41: 572893 | K41: 2399 | L41: 45938 | M41: 859827 | N41: 2399 | O41: 45967 | P41: 274544 | Q41: 2399 | R41: 45997 | S41: 436129 | T41: 2399 | U41: 46027 | V41: 77792 | W41: 2399 | X41: 06/112 | Y41: 436129 | Z41: 2399 | AA41: 46055 | AB41: 458714 | AC41: 2399 | AD41: 46087 | AE41: 565064 | AF41: 2399 | AG41: 46120 | AH41: 3380020 | AI41: $2,399 (cole normal) diferencia material siguiente año ($501) | AJ41: 46147 | AK41: 504750 | AL41: 2399 | AM41: 46181 | AN41: 43839199 | AO41: $2,399 (cole normal) diferencia material siguiente año ($501) | AP41: NO FACT
D42: =D14 -> DOMINIC GUSTAVO NIVON OROZCO | E42: 2559 | F42: 46207 | G42: 62272735 | H42: 2559 | I42: 45905 | J42: 8.5908018e+16 | K42: 2559 | L42: 45933 | M42: 8.5908454e+16 | N42: 2559 | O42: 45966 | P42: 8.5903362e+16 | Q42: 2559 | R42: 45997 | S42: 8.5901018e+16 | T42: 2559 | U42: 46027 | V42: 548976 | W42: 2559 | X42: 45997 | Y42: 8.5901018e+16 | Z42: 2559 | AA42: 46057 | AB42: 28918961 | AC42: 2559 | AD42: 46083 | AE42: 820633 | AF42: 2559 | AG42: 46116 | AH42: 63225954 | AI42: 2559 | AJ42: 46146 | AK42: 8.5902392e+16 | AL42: 2559 | AM42: 46174 | AN42: 315260 | AO42: FACT OK
D43: =D15 -> LUIS MARIO HERNANDEZ VARGAS | H43: 2239 | I43: 45912 | J43: 4215190 | K43: 2239.3 | L43: 45935 | M43: 281018 | N43: 2559 | O43: 45967 | P43: 40741 | Q43: 2239 | R43: 46386 | S43: 3332905 | T43: 2239 | U43: 46023 | V43: 3332905 | Z43: 2239 | AA43: 46067 | AB43: 2345294 | AC43: 2239 | AD43: 46129 | AE43: 5268183 | AF43: 2239 | AG43: 46129 | AH43: 9900530 | AI43: 2239.3 | AJ43: 46170 | AK43: 8365018 | AL43: 2239.3 | AM43: 46184 | AN43: 4124157
D44: =D16 -> ROMINA RODRIGUEZ PEREZ | H44: 2879 | I44: 45915 | J44: 71746458 | K44: 2879 | L44: 45945 | M44: 8843465 | N44: 2879 | O44: 45960 | P44: 12364113 | Q44: 2879 | R44: 46006 | S44: 27548151 | T44: 2879 | U44: 46027 | V44: 88740576 | Z44: 2879 | AA44: 46057 | AB44: 66470624 | AC44: 2879 | AD44: 46081 | AE44: 54003840 | AF44: 2879 | AG44: 46127 | AH44: 19864641 | AI44: 3279 | AJ44: 46155 | AK44: 54638119 | AL44: 3279 | AM44: 46179 | AN44: 7932841 | AO44: FACT OK
D45: =D17 -> JOSE MIGUEL CRUZ LOPEZ | H45: 2687.6 | I45: 45901 | J45: 18569766 | K45: 2687 | L45: 45938 | M45: 98547924 | N45: 2394 | O45: 45966 | P45: 68654212 | Q45: 2687.6 | R45: 45996 | S45: 16809912 | T45: 2687.6 | U45: 46022 | V45: 53321648 | Z45: 2687.6 | AA45: 46056 | AB45: 72596916 | AC45: 2687.6 | AD45: 46084 | AE45: 62176790 | AF45: 2687.6 | AG45: 46116 | AH45: 40066842 | AI45: 2687.6 | AJ45: 46146 | AK45: 39668816 | AL45: 2687.6 | AM45: 46177 | AN45: 14061067 | AO45: FACT OK
C46: 12 MESES | D46: =D18 -> INGRID PATRICIA GUZMAN SANTIAGO | H46: 2559 | I46: 45891 | J46: 570485 | K46: 2559 | L46: 45920 | M46: 734775 | N46: 2559 | O46: 45979 | P46: 63257132 | Q46: 2559 | R46: 45996 | S46: 548799 | T46: 2559 | U46: 46025 | V46: 80482146 | W46: 2560 | X46: 46003 | Y46: 887949 | Z46: 2559 | AA46: 46057 | AB46: 520333 | AC46: 2559 | AD46: 46086 | AE46: 87963547 | AF46: 2259 | AG46: 46116 | AH46: 32250109 | AI46: 2259 | AJ46: 46147 | AK46: 72960374 | AL46: 2559 | AM46: 46177 | AN46: 40970035 | AO46: pago $600, por la difrencia de las colegiaturas de abril y mayo | AP46: FACT OK
D47: =D19 -> EMMA SOFIA DOMINGUEZ NIETO | H47: 2878 | I47: 45903 | J47: 34580363 | K47: 2878 | L47: 45932 | M47: 21646416 | N47: 2878 | O47: 45965 | P47: 37680345 | Q47: 2878 | R47: 45993 | S47: 31484078 | T47: 2878 | U47: 46027 | V47: 47813707 | Z47: 2878 | AA47: 46056 | AB47: 98814826 | AC47: 2878 | AD47: 46086 | AE47: 37779636 | AF47: 2878 | AG47: 46119 | AH47: 26035745 | AI47: 2878 | AJ47: 46126 | AK47: 32504668 | AL47: 2878 | AM47: 46157 | AN47: 40620357 | AO47: FACT OK
...

Sheet 3° P
F1: Centro de Investigación Educativa Colegio San Diego | S1: ACEPTADOS POR CORPORATIVO
F2: Punta el Campanario #183 Col. Bahia de San Martín CP 96536 | S2: PAGOS DE HIJOS DE MAESTROS
F3: PREESCOLAR 30PJN1037Z PRIMARIA 30PPR3773B SECUNDARIA 30PES0033G | S3: MES PAGADO
D4: FACTURA | F4: CICLO ESCOLAR 2024-2025 | S4: ALUMNO DADO DE BAJA
B7: N° | C7: MATRICULA | D7: NOMBRE DEL ALUMNO | E7: PROMOCION | F7: INSCRIPCION | G7: FOLIO | H7: FECHA | I7: MATERIAL | J7: FECHA | K7: FOLIO | L7: ARANCEL | M7: FECHA | N7: FOLIO | O7: LIBROS | P7: FECHA | Q7: FOLIO | R7: UNIFORMES | S7: FECHA | T7: FOLIO | U7: PLAN PAGO | V7: BECA | W7: COLEG | X7: TOTAL
A8: 921 207 3167 | C8: REINSCRIPCIÓN | D8: ALICE YANELI SALINAS TOLEDO | E8: NOVIEMBRE-DICIEMBRE | F8: 1550 | G8: 287318 | H8: 45657 | I8: 2690 | J8: 45889 | K8: 164200 | O8: 5900 | P8: 45900 | Q8: 310825 | U8: 10 meses | V8: 0.3 | W8: 3838 | X8: 2686
A9: 921 123 1837 | C9: ARANCEL AL 20% DE DESCUENTO | D9: KAORU HIGASHI ALCANTARA | E9: ENERO-FEBRERO | F9: 1550 | G9: 3910305 | H9: 45694 | I9: 2690 | J9: 45694 | K9: HSBC013246 | L9: 1992 | M9: 45695 | N9: HSBC013246 | U9: 10 meses | V9: 0.25 | W9: 3838 | X9: 2686
A10: 921 110 3093 | B10: AGREGAR A CONTACTO | C10: NUEVO INGRESO | D10: AGNES DANIELLE JIMENEZ CALDERON | E10: MARZO-JUNIO | F10: GRATIS | G10: GRATIS | H10: 45877 | I10: 2690 | J10: 45803 | K10: 67848127 | L10: 2490 | M10: 45877 | N10: 90510FS00962067214 | O10: 5500 | P10: 45877 | Q10: 65669 | R10: 1755 | S10: 45888 | T10: 27388321 | U10: 10 meses | V10: 0.3 | W10: 3838 | X10: 2686
A11: 921 123 0949 | C11: REINSCRIPCIÓN | D11: CESAR MATEO CRUZ LANDA | E11: ENERO-FEBRERO | F11: 1550 | G11: 8776707083 | H11: 45705 | I11: 2690 | J11: 45931 | K11: 12640830 | L11: 2490 | M11: 45705 | N11: 8776707083 | O11: 5900 | P11: 45862 | Q11: 21849877 | U11: 12 meses | V11: 0.25 | W11: 3838 | X11: 2559
A12: 921 256 0669 | C12: NUEVO INGRESO | D12: THIAGO ALFONSO FUENTES | E12: ENERO-FEBRERO | F12: 1550 | G12: HSBC5537 | H12: 45712 | I12: 2690 | J12: 45712 | K12: HSBC5537 | L12: 2490 | M12: 45712 | N12: HSBC5537 | O12: 4000 | P12: 45810 | Q12: BANORTE5537 | U12: 12 meses | V12: 0.3 | W12: 3199 | X12: 2239.3
A13: 921 345 7203 | C13: NUEVO INGRESO | D13: ISABELLA FERNANDA PEREZ VELAZQUEZ | E13: ENERO-FEBRERO | F13: 1550 | G13: 174622771 | H13: 45721 | I13: 2690 | J13: 45721 | K13: 174622771 | L13: 2490 | M13: 45721 | N13: 174622771 | R13: 3085 | S13: 45897 | T13: 2808250 | U13: 10 meses | V13: 0.3 | W13: 3838 | X13: 2686
A14: 921 101 3834 | C14: REINSCRIPCIÓN | D14: ASIEL ROQUE FUENTES | E14: ENERO-FEBRERO | F14: 1550 | G14: 7584919327 | H14: 45807 | I14: 2690 | J14: 45807 | K14: 7584919327 | L14: 2490 | M14: 45807 | N14: 7584919327 | U14: 10 meses | V14: 0.2 | W14: 3838 | X14: 3071
A15: 921 147 1116 | C15: REINSCRIPCIÓN | D15: ALEXANDRO VIDAL APOLINAR VELAZQUEZ | E15: MARZO-JUNIO | F15: 1860 | G15: 3006250 | H15: 45838 | I15: 2690 | J15: 45838 | K15: 3006250 | L15: 2490 | M15: 45838 | N15: 3006250 | O15: 5900 | P15: 45868 | Q15: 85902586874321100´
A16: 921 112 7464 | C16: REINSCRIPCIÓN | D16: AZAEL BAILON CANCINO | E16: MARZO-JUNIO | F16: 1860 | G16: 94628 | H16: 45839 | I16: 2690 | J16: 45871 | K16: 8.5902004e+16 | L16: 2490 | M16: 45839 | N16: 94628 | O16: 5900 | P16: 45871 | Q16: 8.5902004e+16
A17: 556 932 1515 | C17: NUEVO INGRESO | D17: MATEO CRUZ PORTILLA | E17: MARZO-JUNIO | F17: 1860 | G17: 5020242 | H17: 45853 | I17: 2690 | J17: 45853 | K17: 5020242 | L17: 2490 | M17: 45853 | N17: 5020242 | O17: 5900 | P17: 45897 | Q17: 5022242
A18: 921 305 2090 | C18: NUEVO INGRESO | D18: DEREK ABDIEL PECH SANTIAGO | E18: MARZO-JUNIO | F18: 1860 | G18: 26500582 | H18: 45845 | L18: 2490 | M18: 45845 | N18: 40017281 | O18: 5900 | P18: 45860 | Q18: 11469359
A19: 921 154 9372 | C19: REINSCRIPCIÓN | D19: DIEGO LARA BARRERA | E19: MARZO-JUNIO | F19: 1860 | G19: HSB5544347 | H19: 45852 | I19: 2690 | J19: 46148 | K19: 57660 | L19: 2490 | M19: 46148 | N19: 57666 | O19: 5900 | P19: 45852 | Q19: HSB5544347
A20: 922 127 2139 | C20: REINSCRIPCIÓN | D20: SEBASTIAN CARRASCO RAMIREZ | E20: MARZO-JUNIO | F20: 2X1 | G20: 2X1 | H20: 45854 | I20: 2690 | J20: 45854 | K20: 250716 | L20: 2490 | M20: 45854 | N20: 250716 | O20: 5900 | P20: 45854 | Q20: 250716
A21: 229 124 7667 | C21: REINSCRIPCIÓN | D21: MARCELO IVAN CRUZ GARCIA | E21: MARZO-JUNIO | F21: 1860 | G21: 785296355 | H21: 45810 | I21: 2690 | J21: 45855 | K21: 785296355 | L21: 2490 | M21: 45810 | N21: 785296355 | O21: 5900 | P21: 45874 | Q21: 26341385
A22: 921 192 2612 | C22: NUEVO INGRESO | D22: JOSUE VALENCIA OCAMPO | E22: MARZO-JUNIO | F22: 1860 | G22: 21370334 | H22: 45856 | I22: 2690 | J22: 45856 | K22: 213703334 | O22: 5900 | P22: 45897 | Q22: 1748 | X22: 2686
A23: 993 397 1246 | C23: REINSCRIPCIÓN | D23: JUAN SEBASTIAN PEREZ SANTOS | E23: MARZO-JUNIO | F23: GRATIS | G23: GRATIS | H23: 45863 | L23: 2490 | M23: 45863 | N23: 56006 | O23: 4200 | P23: 46086
A24: 921 151 4694 | C24: NUEVO INGRESO | D24: GABRIEL ARRIAGA PEREZ | E24: MARZO-JUNIO | F24: 1743 | G24: 35678624 | H24: 45859 | I24: 1883 | J24: 45866 | K24: 75239048 | L24: 1743 | M24: 45859 | N24: 35678624 | O24: 5900 | P24: 45901 | Q24: 56010377´
A25: 921 136 9723 | C25: REINSCRIPCIÓN | D25: LUIS EDUARDO GUITARTH MARTINEZ | E25: MARZO-JUNIO | F25: GRATIS | G25: GRATIS | H25: 45877 | L25: 1550 | M25: 45877 | N25: 90510FS00962067214 | O25: 5500 | P25: 45877 | Q25: 65669 | U25: 10 MESES | V25: 0.25 | W25: 3838.8 | X25: 2879
A26: 921 252 7975 | C26: SIMON BOLIBAR | D26: CLAUDIA MARIA CASTRO CAMACHO | E26: MARZO-JUNIO | F26: GRATIS | G26: GRATIS | H26: 45883 | I26: 1883 | J26: 45915 | K26: 404260 | L26: 1550 | M26: 45915 | N26: 404260 | O26: 3000 | P26: 45915 | Q26: 404260
C27: REINSCRIPCIÓN | D27: LIAM HANIEL ROBLES LIMON | E27: MARZO-JUNIO | F27: 1860 | G27: 93996052 | H27: 45835 | I27: 2690 | J27: 45835 | K27: 93996052 | L27: 2490 | M27: 45835 | N27: 93996052 | O27: 5900 | P27: 45884 | Q27: 4514232 | U27: 10 MESES | V27: 0.25 | W27: 3838.8 | X27: 2879
A28: 938 180 0913 | C28: NUEVO INGRESO | D28: DIANA MARTINEZ MENDOZA | E28: MARZO-JUNIO | F28: GRATIS | G28: GRATIS | H28: 45889 | I28: 1345 | J28: 45889 | K28: 2008250 | L28: 1245 | M28: 45889 | N28: 2008250
A29: 921 257 2547 | C29: SIMON BOLIBAR | D29: CONTRERAS PALACIONS KEIDY ISABELLA | E29: MARZO-JUNIO | F29: GRATIS | G29: GRATIS | H29: 45894 | U29: 12 meses | V29: 0.3 | W29: 3838 | X29: 3239
A30: 921 221 5011 | C30: NUEVO INGRESO | D30: ATENEA ALESSANDRA USCANGA TOLEDO | E30: MARZO-JUNIO | F30: 1860 | G30: 36644385 | H30: 45862 | I30: 2690 | J30: 45862 | K30: 36644385 | L30: 2490 | M30: 45862 | N30: 36644385 | O30: 5900 | P30: 45870 | Q30: 57211632 | U30: 12 meses | V30: 0.2 | W30: 3838 | X30: 2623
A31: 921 240 2488 | C31: SIMON BOLIBAR | D31: KAREN ITZEL VÉLAZQUEZ JIMENEZ | E31: MARZO-JUNIO | F31: GRATIS | G31: GRATIS | H31: 45884 | I31: 1245 | J31: 45922 | K31: 15661754 | L31: 1345 | M31: 45922 | N31: 29462213 | O31: 5900 | P31: 45898 | Q31: 65092656 | R31: 2045 | S31: 45898 | T31: 65092656
B39: COLEGIATURA
B40: N° | C40: MATRICULA | D40: NOMBRE DEL ALUMNO | E40: AGOSTO | H40: SEPTIEMBRE | K40: OCTUBRE | N40: NOVIEMBRE | Q40: DICIEMBRE | T40: ENERO | W40: JULIO | Z40: FEBRERO | AC40: MARZO | AF40: ABRIL | AI40: MAYO | AL40: JUNIO
E41: MONTO | F41: FECHA | G41: FOLIO | H41: MONTO | I41: FECHA | J41: FOLIO | K41: MONTO | L41: FECHA | M41: FOLIO | N41: MONTO | O41: FECHA | P41: FOLIO | Q41: MONTO | R41: FECHA | S41: FOLIO | T41: MONTO | U41: FECHA | V41: FOLIO | W41: MONTO | X41: FECHA | Y41: FOLIO | Z41: MONTO | AA41: FECHA | AB41: FOLIO | AC41: MONTO | AD41: FECHA | AE41: FOLIO | AF41: MONTO | AG41: FECHA | AH41: FOLIO | AI41: MONTO | AJ41: FECHA | AK41: FOLIO | AL41: MONTO | AM41: FECHA | AN41: FOLIO
D42: =D8 -> ALICE YANELI SALINAS TOLEDO | H42: 2494.75 | I42: 45900 | J42: 300825 | K42: 2494.75 | L42: 45935 | M42: 61025 | N42: 2494.75 | O42: 45966 | P42: 1615258 | Q42: 2494.75 | R42: 45993 | S42: 101226 | T42: 2696 | U42: 46022 | V42: 10126 | Z42: 2696 | AA42: 46022 | AB42: 28994436 | AC42: 2696 | AD42: 46084 | AE42: 13205 | AF42: 3094 | AG42: 46144 | AH42: 31434955 | AI42: 2696 | AJ42: 46147 | AK42: 87435645 | AL42: 2696 | AM42: 46178 | AN42: 59924705 | AO42: no fact
C43: PAGO ANUAL | D43: =D9 -> KAORU HIGASHI ALCANTARA | H43: 2686 | I43: 45636 | J43: PAGO TARJETA | K43: 2686 | L43: 46001 | M43: PAGO TARJETA | N43: 2686 | O43: 45636 | P43: PAGO TARJETA | Q43: 2686 | R43: 46001 | S43: PAGO TARJETA | T43: 2686 | U43: 46001 | V43: PAGO TARJETA | Z43: 2686 | AA43: 46001 | AB43: PAGO TARJETA | AC43: 2686 | AD43: 46001 | AE43: PAGO TARJETA | AF43: 2686 | AG43: 46001 | AH43: PAGO TARJETA | AO43: fact ok
D44: =D10 -> AGNES DANIELLE JIMENEZ CALDERON | H44: 2686 | I44: 45904 | J44: 54232768 | K44: 2686 | L44: 45935 | M44: 68089812 | N44: 2686 | O44: 45964 | P44: 131756415619 | Q44: 3086 | R44: 46041 | S44: 1856412 | Z44: 2686 | AA44: 46056 | AB44: 1454302255001 | AC44: 2686 | AD44: 46074 | AE44: 1856412 | AH44: PENDIENTE | AI44: 2686 | AJ44: 46147 | AK44: 157863535380
D45: =D11 -> CESAR MATEO CRUZ LANDA | E45: 2559 | F45: 45750 | G45: 20968661 | H45: 2559 | I45: 45903 | J45: 522224278 | K45: 2559 | L45: 45931 | M45: 3272717 | N45: 2559 | O45: 45963 | P45: 12699903 | Q45: 2559 | R45: 45995 | S45: 72361207 | T45: 2559 | U45: 46027 | V45: 617550 | W45: 2559 | X45: 46013 | Y45: 31898027 | Z45: 2559 | AA45: 46057 | AB45: 12399279 | AC45: 2559 | AD45: 46083 | AE45: 32751424 | AF45: 2559 | AG45: 46116 | AH45: 42076800 | AI45: 2559 | AJ45: 46146 | AK45: 91511543 | AL45: 2559 | AM45: 46176 | AN45: 14047772 | AO45: fact ok
D46: =D12 -> THIAGO ALFONSO FUENTES | H46: 2239 | I46: 45903 | J46: 5537 | K46: 2239 | L46: 45934 | M46: 5537 | N46: 2239 | O46: 45967 | P46: CUENTA5539 | Q46: 2239 | R46: 45997 | S46: cuenta5537 | T46: 2559 | U46: 46037 | V46: HSBC088684 | Z46: 2559 | AA46: 46068 | AB46: CUENTA5537 | AC46: 2239 | AD46: 46082 | AE46: 5537 | AF46: 2239 | AG46: 46116 | AH46: cta5537 | AI46: 2239 | AJ46: 46144 | AK46: SF | AL46: 2239 | AM46: 07706/2026 | AN46: SF | AO46: fact ok
D47: =D13 -> ISABELLA FERNANDA PEREZ VELAZQUEZ | H47: 2559 | I47: 45901 | J47: 98502613 | K47: 2686 | L47: 45936 | M47: 910251 | N47: 2686 | O47: 45967 | P47: 47512693 | Q47: 2686 | R47: 45997 | S47: 9875463214 | T47: 2686 | U47: 46026 | V47: 1301260 | Z47: 2686 | AA47: 46082 | AB47: 73962594 | AC47: 2686 | AD47: 46124 | AE47: 90570999 | AF47: 2686 | AG47: 46133 | AH47: 2686 | AI47: 2728 | AJ47: 46148 | AK47: 11610122 | AL47: 2728 | AM47: 46177 | AN47: 45676335 | AO47: fact ok
D48: =D14 -> ASIEL ROQUE FUENTES | H48: 2686 | I48: 45901 | J48: 14157685 | K48: 3071 | L48: 45931 | M48: 6947927 | N48: 3071 | O48: 45964 | P48: 7507982 | Q48: 3071 | R48: 45994 | S48: 9025676 | T48: 3071 | U48: 46024 | V48: 54897621 | Z48: 3071 | AA48: 46055 | AB48: 4584316 | AC48: 3071 | AD48: 46086 | AE48: 77568016 | AF48: 3071 | AG48: 46113 | AH48: 6932914 | AI48: 3071 | AJ48: 46145 | AK48: 69346061 | AL48: 3071 | AM48: 46177 | AN48: 18480826 | AO48: fact ok
D49: =D15 -> ALEXANDRO VIDAL APOLINAR VELAZQUEZ | H49: 2559 | I49: 45901 | J49: APROB 4854 | K49: 2559 | L49: 45901 | M49: APROB 4854 | N49: 2559 | O49: 45901 | P49: APROB 4854 | Q49: 2559 | R49: 45901 | S49: APROB 4854 | T49: 2559 | U49: 45901 | V49: APROB 4854 | Z49: 2559 | AA49: 46058 | AB49: 50113171 | AC49: 2559 | AD49: 46058 | AE49: 50113171 | AF49: 2559 | AG49: 46058 | AH49: 50113171 | AI49: 2559 | AJ49: 46058 | AK49: 50113171 | AL49: 2559 | AM49: 46058 | AN49: 50113171 | AO49: fact ok
...

Sheet 4°P
F1: Centro de Investigación Educativa Colegio San Diego | S1: ACEPTADOS POR CORPORATIVO
F2: Punta el Campanario #183 Col. Bahia de San Martín CP 96536 | S2: PAGOS DE HIJOS DE MAESTROS
F3: PREESCOLAR 30PJN1037Z PRIMARIA 30PPR3773B SECUNDARIA 30PES0033G | S3: MES PAGADO
D4: FACTURA | F4: CICLO ESCOLAR 2024-2025 | S4: ALUMNO DADO DE BAJA
B7: N° | C7: MATRICULA | D7: NOMBRE DEL ALUMNO | E7: PROMOCION | F7: INSCRIPCION | G7: FOLIO | H7: FECHA | I7: MATERIAL | J7: FECHA | K7: FOLIO | L7: ARANCEL | M7: FECHA | N7: FOLIO | O7: LIBROS | P7: FECHA | Q7: FOLIO | R7: UNIFORMES | S7: FECHA | T7: FOLIO | U7: PLAN PAGO | V7: BECA | W7: COLEG | X7: TOTAL
A8: 782 829 8093
A9: 921 261 1444 | C9: 20% DESCUENTO ARANCEL | D9: EMIR ELÍAS GUZMÁN POSADAS | E9: ENERO- FEBRERO | F9: 1550 | G9: 2402250 | H9: 45712 | I9: 2690 | J9: 45838 | K9: 8.5900054e+16 | L9: 1992 | M9: 45712 | N9: 2402250 | O9: 4000 | P9: 45901 | Q9: 8.5905693e+16 | U9: 12 MESES | V9: 0.2 | W9: 3199 | X9: 2559
A10: 921 246 4886 | C10: REINSCRIPCIÓN | D10: MARIA ESTHER HERNANDEZ VARGAS | E10: ENERO- FEBRERO | F10: 1550 | G10: HSBC344475 | H10: 45716 | I10: 2690 | J10: 45866 | K10: 9300304 | L10: 1992 | M10: 45866 | N10: 291018 | O10: 5900 | P10: 45957 | Q10: 281018
A11: Papá:916 116 2460/mamá 921 240 5771 | C11: NUEVO INGRESO | D11: EMILIANO NARVAEZ MARTINEZ | E11: ENERO- FEBRERO | F11: GRATIS | G11: GRATIS | H11: 45898 | I11: 1345 | J11: 45899 | K11: Pago con tarjeta | L11: 1245 | M11: 45899 | N11: Pago con tarjeta | O11: 5900 | P11: 45928 | Q11: 14597856 | U11: 12 MESES | V11: 0.3 | W11: 3199 | X11: 2239
A12: 921 256 2170 | C12: NUEVO INGRESO | D12: ALANA XIMENA CASTILLO ABREU | E12: ENERO- FEBRERO | F12: GRATIS | G12: GRATIS | H12: GRATIS | I12: 2690 | J12: 45824 | K12: 98851283 | L12: 2490 | M12: 45824 | N12: 988851283 | O12: 5900 | P12: 45884 | Q12: 71494998 | U12: 10 MESES | V12: 0.25 | W12: 3838.8 | X12: 2879
A13: 921 276 2448 | C13: REINSCRIPCIÓN | D13: FRANCISCO MALIK HEREDIA DOMÍNGUEZ | E13: MARZO-JUNIO | F13: 1860 | G13: 250708 | H13: 45846 | I13: 2690 | J13: 45846 | K13: 250708 | L13: 2490 | M13: 45854 | N13: 250708 | O13: 5900 | P13: 45887 | Q13: 250818 | U13: 10 MESES | V13: 0.18 | W13: 3838.8 | X13: 3147
A14: 921 134 7825 | C14: NUEVO INGRESO | D14: JOSE MARIA MARTINEZ TADEO | E14: MARZO-JUNIO | F14: GRATIS | G14: GRATIS | H14: 45898 | I14: 2690 | J14: 45900 | K14: 585317 | L14: 2490 | M14: 45900 | N14: 5851317 | O14: 5900 | P14: 45901 | Q14: 1303670
A15: 921 140 2401 | C15: REINSCRIPCIÓN | D15: MIRANDA REYES ESCOBAR | E15: MARZO-JUNIO | F15: GRATIS | G15: GRATIS | H15: 45901 | U15: 10 MESES | V15: 0.3 | W15: 3838.8 | X15: 2687
A16: 921 140 2401 | C16: REINSCRIPCIÓN | D16: CONSTANZA REYES ESCOBAR | E16: MARZO-JUNIO | F16: GRATIS | G16: GRATIS | H16: 45901 | U16: 10 MESES | V16: 0.3 | W16: 3838.8 | X16: 2687
B29: COLEGIATURA
B30: N° | C30: MATRICULA | D30: NOMBRE DEL ALUMNO | E30: AGOSTO | H30: SEPTIEMBRE | K30: OCTUBRE | N30: NOVIEMBRE | Q30: DICIEMBRE | T30: ENERO | W30: JULIO | Z30: FEBRERO | AC30: MARZO | AF30: ABRIL | AI30: MAYO | AL30: JUNIO
C32: FACT | D32: =D9 -> EMIR ELÍAS GUZMÁN POSADAS | E32: 2559 | F32: 45874 | G32: 39874855 | H32: 2559 | I32: 45910 | J32: 38736109 | K32: 2559 | L32: 45936 | M32: 8.5904479e+16 | N32: 2559 | O32: 45967 | P32: 55116694 | Q32: 2559 | R32: 45997 | S32: 58628374 | T32: 2559 | U32: 46027 | V32: 17895983 | Z32: 2559 | AA32: 46055 | AB32: 19010475 | AC32: 2559 | AD32: 46086 | AE32: 59573223 | AF32: 2559 | AG32: 46117 | AH32: 66843314 | AI32: 2559 | AJ32: 46147 | AK32: 10040008 | AL32: 2559 | AM32: 46181 | AN32: 959113 TC | AO32: fact ok
D33: =D10 -> MARIA ESTHER HERNANDEZ VARGAS | H33: 2239 | I33: 45912 | J33: 4121821 | K33: 2239.3 | L33: 45935 | M33: 281018 | N33: 2239 | O33: 45967 | P33: 40741 | Q33: 2239 | R33: 46386 | S33: 7604251 | T33: 2239 | U33: 46023 | V33: 1755783 | Z33: 2239 | AA33: 46087 | AB33: 6879938 | AC33: 2239 | AD33: 46129 | AE33: 85534 | AF33: 2239 | AG33: 46129 | AH33: 6919545 | AI33: 2239.3 | AJ33: 46156 | AK33: 9106373 | AL33: 2239.3 | AM33: 46177 | AN33: 2068462 | AO33: fact ok
D34: =D11 -> EMILIANO NARVAEZ MARTINEZ | H34: 2239 | I34: 45906 | J34: 38975648 | K34: 2239 | L34: 45936 | M34: 8.5901442e+16 | N34: 2239 | O34: 45966 | P34: 8.5900663e+16 | Q34: 2239 | R34: 45996 | S34: 8.5900999e+16 | T34: 2239 | U34: 46027 | V34: 8.5909704e+16 | Z34: 2239 | AA34: 46057 | AB34: 8.59078e+16 | AC34: 2239 | AD34: 46085 | AE34: 8.5907614e+16 | AF34: 2239 | AG34: 46117 | AH34: 8.5908582e+16 | AI34: 2240 | AJ34: 46146 | AK34: 312469
D35: =D12 -> ALANA XIMENA CASTILLO ABREU | H35: 2879 | I35: 45909 | J35: 395842 | K35: 2879 | L35: 45936 | M35: 32DNDI | N35: 2879 | O35: 45966 | P35: 493600 | Q35: 2879 | R35: 45996 | S35: 90846355 | T35: 3279 | U35: 46036 | V35: DEBITCARD | Z35: 2879 | AA35: 46056 | AB35: 477986 | AC35: 2879 | AD35: 46086 | AE35: 201243 | AF35: 2879 | AG35: 46117 | AH35: 56879412 | AI35: 2879 | AJ35: 46147 | AK35: 23254008 | AL35: 2879 | AM35: 46178 | AN35: 61453777 | AO35: fact ok
D36: =D13 -> FRANCISCO MALIK HEREDIA DOMÍNGUEZ | H36: 3147 | I36: 45905 | J36: 250905 | K36: 3147 | L36: 45935 | M36: 251005 | N36: 3147 | O36: 45966 | P36: 251105 | Q36: 3147 | R36: 45996 | S36: 251205 | T36: 3147 | U36: 46027 | V36: 260105 | Z36: 3147 | AA36: 46144 | AB36: 260205 | AC36: 3147 | AD36: 46086 | AE36: 260305 | AF36: 3147 | AG36: 46118 | AH36: 260406 | AI36: 3147 | AJ36: 46147 | AK36: 604917 | AL36: 3147 | AM36: 46178 | AN36: 326879 | AO36: no fact
D37: =D14 -> JOSE MARIA MARTINEZ TADEO | H37: 2623 | I37: 45905 | J37: 3136259 | K37: 2623 | L37: 45939 | M37: 3050285 | N37: 3023 | O37: 46032 | P37: 8.5901319e+16 | Q37: 3023 | R37: 46032 | S37: 8.5901319e+16 | T37: 3023 | U37: 46032 | V37: 8.5901319e+16 | Z37: 3023 | AA37: 46032 | AB37: 8.5901319e+16 | AC37: 3023 | AD37: 46103 | AE37: 8.5900562e+16 | AF37: 3023 | AG37: 46103 | AH37: SF
D38: =D15 -> MIRANDA REYES ESCOBAR | H38: 2680 | I38: 45906 | J38: 76206548 | K38: 2680 | L38: 45934 | M38: 58649042 | N38: 2680 | O38: 45966 | P38: SF | Q38: 2680 | R38: 45996 | S38: SF | T38: 2680 | U38: 46027 | V38: 28235253 | Z38: 2680 | AA38: 46027 | AB38: TRANSF | AC38: 2680 | AD38: 46087 | AE38: 91378914 | AF38: 2680 | AG38: 46117 | AH38: 1584619706
D39: =D16 -> CONSTANZA REYES ESCOBAR | H39: 2680 | I39: 45906 | J39: 53949849 | K39: 2680 | L39: 45934 | M39: 22966164 | N39: 2680 | O39: 45966 | P39: SF | Q39: 2680 | R39: 45996 | S39: SF | T39: 2680 | U39: 46027 | V39: 98405673 | Z39: 2680 | AA39: 46027 | AB39: TRANSF | AC39: 2680 | AD39: 46087 | AE39: 87987959 | AF39: 2680 | AG39: 46117 | AH39: 1584619706
H50: 2879

Sheet 5°P
F1: Centro de Investigación Educativa Colegio San Diego | S1: ACEPTADOS POR CORPORATIVO
F2: Punta el Campanario #183 Col. Bahia de San Martín CP 96536 | S2: PAGOS DE HIJOS DE MAESTROS
F3: PREESCOLAR 30PJN1037Z PRIMARIA 30PPR3773B SECUNDARIA 30PES0033G | S3: MES PAGADO
D4: FACTURA | F4: CICLO ESCOLAR 2024-2025 | S4: ALUMNO DADO DE BAJA
B7: N° | C7: MATRICULA | D7: NOMBRE DEL ALUMNO | E7: PROMOCION | F7: INSCRIPCION | G7: FOLIO | H7: FECHA | I7: MATERIAL | J7: FECHA | K7: FOLIO | L7: ARANCEL | M7: FECHA | N7: FOLIO | O7: LIBROS | P7: FECHA | Q7: FOLIO | R7: UNIFORMES | S7: FECHA | T7: FOLIO | U7: PLAN PAGO | V7: BECA | W7: COLEG | X7: TOTAL
A8: 921 305 2256 | B8: REINSCRITO | D8: DERECK BONILLA MARTINEZ | E8: NOVIEMBRE-DICIEMBRE | F8: 1550 | G8: SF | H8: 45630 | I8: 2690 | J8: 45749 | K8: 2579868815 | O8: 5900 | P8: 45804 | Q8: 7356956565
A9: 921 172 7241 | B9: REINSCRITO | D9: RODRIGO SORIANO LAVÍN | E9: NOVIEMBRE-DICIEMBRE | F9: 1550 | G9: 4837211 | H9: 45608 | O9: 1000 | P9: 45871 | Q9: 20825 | U9: 10 MESES | V9: 0.3 | W9: 3838 | X9: 2686
A10: 782 136 4624 | B10: REINSCRITO | D10: GUTIERREZ VEGA DAYRA VANESA | E10: NOVIEMBRE-DICIEMBRE | F10: 1550 | G10: 8.5902125e+16 | H10: 45656 | I10: 2690 | J10: 45656 | K10: 8.5902125e+16 | L10: 2490 | M10: 45656 | N10: 8.5902125e+16 | O10: 5500 | P10: 45805 | Q10: 8.5903073e+16
A11: 921 177 3402 | B11: REINSCRITO | D11: RAUL MANUEL HAMILTON ARIAS | E11: NOVIEMBRE-DICIEMBRE | F11: 1550 | G11: SF | H11: 45656 | I11: 2690 | J11: 45908 | L11: 2490 | M11: 45908 | O11: 5900 | P11: 45910 | Q11: 1096 | U11: 10 MESES | V11: 0.25 | W11: 3838 | X11: 2879
A12: 921 273 2901 | B12: REINSCRITO | D12: LUNA ALEJANDRA OSORIO CARBALLO | E12: ENERO-FEBRERO | F12: 1550 | G12: 90510FS00962067214 | H12: 45693 | O12: 5500 | P12: 45806 | Q12: 65669 | Z12: =3478.8*0.3 -> 1043.64
A13: 921 125 9896 | B13: NUEVO INGRESO | D13: TANIA ALEXA SALVADOR MARTINEZ | E13: ENERO-FEBRERO | F13: 1550 | G13: 9395584719 | H13: 45712 | I13: 1345 | J13: 45914 | K13: 10706804 | L13: 1992 | M13: 45712 | N13: 9395584719 | O13: 5900 | P13: 45884 | Q13: 46297519 | R13: 3085 | S13: 45895 | T13: 29558936 | Z13: =3478.8-Z12 -> 2435.16
A14: 921 139 3753 | B14: REINSCRITO | D14: ANGEL MATEO VELAZQUEZ GARCIA | E14: ENERO-FEBRERO | F14: 1550 | G14: 9730089422 | H14: 45716 | I14: 2690 | J14: 45733 | K14: 1187534286 | L14: 2490 | M14: 45716 | N14: 9730089422 | O14: 5900 | P14: 45875 | Q14: 56937164
A15: 921 119 3553 | B15: NUEVO INGRESO | C15: HERMANA DE RENATA SEC COMUNCIARSE CON LA MAMÁ DE RENATA | D15: GISSEL ADHARA LOPEZ CRUZ | E15: MARZO-JUNIO | F15: 1550 | G15: 50725 | H15: 45843 | I15: 2690 | J15: 45897 | K15: SF | L15: 2490 | M15: 45897 | N15: 178267 | O15: 5900 | P15: 45897 | Q15: 178267 | R15: 3085 | S15: 45897 | T15: 178267 | U15: 12 MESES | V15: 0.3 | W15: 3199 | X15: 2239
A16: 921 268 5925 | B16: REINSCRIPCIÓN | D16: MAXIMILIANO CISNEROS VILLEGAS | E16: MARZO-JUNIO | F16: 1700 | G16: 6708635 | H16: 45848 | I16: 2690 | J16: 45748 | K16: 221514 | L16: 790 | M16: 45748 | N16: 221514 | O16: 5900 | P16: 45869 | Q16: 9584764
A17: 922 127 2139 | B17: REINSCRIPCIÓN | D17: ANGEL MATHIAS CARRASCO RAMIREZ | E17: MARZO-JUNIO | F17: 1860 | G17: 250716 | H17: 45854 | I17: 2690 | J17: 45854 | K17: 250716 | L17: 2490 | M17: 45854 | N17: 250716 | O17: 5900 | P17: 45824 | Q17: 250716
A18: 921 192 2612 | B18: NUEVO INGRESO | D18: YESHUA FERNANDO VALENCIA OCAMPO | E18: JULIO | F18: 2X1 | G18: 21370334 | H18: 45856 | I18: 2690 | J18: 45856 | K18: 213703334 | O18: 5900 | P18: 45897 | Q18: 1748
B19: REINSCRIPCIÓN | D19: DANIELA MICHELLE ULIN GARCIA | E19: NOVIEMBRE-DICIEMBRE | F19: 1450 | G19: 4647997 | H19: 45677 | U19: 10 MESES
